Workbook

Sheet 使い方
A1: SNS分析シート(X / Threads)
A3: ※ 現在入っているデータはすべてダミー(サンプル)です。実データに差し替えてご利用ください。
A5: ■ シート構成
A6: ・投稿データ … 1投稿 = 1行。青字の列(A〜K)を入力します。黒字の列(L〜P)は自動計算です。
A7: ・フォロワー推移 … 週1回などの定点で、各SNSのフォロワー数を青字の列に入力します。
A8: ・サマリー … SNS別KPI、投稿タイプ別・曜日別・時間帯別のエンゲージメント率、TOP5投稿を自動集計します。
A10: ■ 色のルール
A11: ・青字 = 手入力するセル / 黒字 = 計算式(触らない)
A13: ■ 実データへの差し替え手順
A14: 1. 「投稿データ」シートのA2:K行のサンプルを削除します(L〜P列の計算式は残してください)。
A15: 2. X: アナリティクス画面から投稿のCSVをエクスポートし、インプレッション・いいね・リポスト・返信・引用・リンククリックを該当列に貼り付けます。
A16: 3. Threads: インサイト画面の投稿ごとの数値(閲覧数・いいね・返信・再投稿・引用)を貼り付けます。リンククリックは取得できないため 0 で構いません。
... A25: ■ 入力例(1行分)
A26: 投稿日 | B26: 時刻 | C26: SNS | D26: 投稿タイプ | E26: 内容メモ | F26: インプレッション | G26: いいね | H26: リポスト | I26: 返信 | J26: 引用 | K26: リンククリック
A27: 46266 | B27: 0.875 | C27: X | D27: 画像 | E27: 新商品の紹介 | F27: 2400 | G27: 38 | H27: 9 | I27: 4 | J27: 1 | K27: 3

Sheet サマリー
A1: SNS分析サマリー(X / Threads)
A2: ="対象期間: "&TEXT(MIN(投稿データ!$A$2:$A$500),"yyyy/mm/dd")&" 〜 "&TEXT(MAX(投稿データ!$A$2:$A$500),"yyyy/mm/dd") -> 対象期間: 2026/07/01 〜 2026/08/31
A4: 1. SNS別 主要KPI
A5: 指標 | B5: X | C5: Threads
A6: 投稿数 | B6: =COUNTIFS(投稿データ!$C$2:$C$500,"X") -> 61 | C6: =COUNTIFS(投稿データ!$C$2:$C$500,"Threads") -> 42
A7: 合計インプレッション | B7: =SUMIFS(投稿データ!$F$2:$F$500,投稿データ!$C$2:$C$500,"X") -> 155776 | C7: =SUMIFS(投稿データ!$F$2:$F$500,投稿データ!$C$2:$C$500,"Threads") -> 58012
A8: 1投稿あたり平均インプレッション | B8: =IF(COUNTIFS(投稿データ!$C$2:$C$500,"X")=0,0,SUMIFS(投稿データ!$F$2:$F$500,投稿データ!$C$2:$C$500,"X")/COUNTIFS(投稿データ!$C$2:$C$500,"X")) -> 2553.7049 | C8: =IF(COUNTIFS(投稿データ!$C$2:$C$500,"Threads")=0,0,SUMIFS(投稿データ!$F$2:$F$500,投稿データ!$C$2:$C$500,"Threads")/COUNTIFS(投稿データ!$C$2:$C$500,"Threads")) -> 1381.2381
A9: 合計エンゲージメント | B9: =SUMIFS(投稿データ!$L$2:$L$500,投稿データ!$C$2:$C$500,"X") -> 3597 | C9: =SUMIFS(投稿データ!$L$2:$L$500,投稿データ!$C$2:$C$500,"Threads") -> 2676
A10: エンゲージメント率 | B10: =IF(SUMIFS(投稿データ!$F$2:$F$500,投稿データ!$C$2:$C$500,"X")=0,0,SUMIFS(投稿データ!$L$2:$L$500,投稿データ!$C$2:$C$500,"X")/SUMIFS(投稿データ!$F$2:$F$500,投稿データ!$C$2:$C$500,"X")) -> 0.023090848 | C10: =IF(SUMIFS(投稿データ!$F$2:$F$500,投稿データ!$C$2:$C$500,"Threads")=0,0,SUMIFS(投稿データ!$L$2:$L$500,投稿データ!$C$2:$C$500,"Threads")/SUMIFS(投稿データ!$F$2:$F$500,投稿データ!$C$2:$C$500,"Threads")) -> 0.046128387
A11: 合計いいね | B11: =SUMIFS(投稿データ!$G$2:$G$500,投稿データ!$C$2:$C$500,"X") -> 2411 | C11: =SUMIFS(投稿データ!$G$2:$G$500,投稿データ!$C$2:$C$500,"Threads") -> 1765
A12: 合計リポスト | B12: =SUMIFS(投稿データ!$H$2:$H$500,投稿データ!$C$2:$C$500,"X") -> 521 | C12: =SUMIFS(投稿データ!$H$2:$H$500,投稿データ!$C$2:$C$500,"Threads") -> 208
A13: 合計返信 | B13: =SUMIFS(投稿データ!$I$2:$I$500,投稿データ!$C$2:$C$500,"X") -> 322 | C13: =SUMIFS(投稿データ!$I$2:$I$500,投稿データ!$C$2:$C$500,"Threads") -> 610
A14: 合計リンククリック | B14: =SUMIFS(投稿データ!$K$2:$K$500,投稿データ!$C$2:$C$500,"X") -> 215 | C14: =SUMIFS(投稿データ!$K$2:$K$500,投稿データ!$C$2:$C$500,"Threads") -> 0
A15: 最新フォロワー数 | B15: =INDEX(フォロワー推移!$B$2:$B$500,COUNT(フォロワー推移!$A$2:$A$500)) -> 3991 | C15: =INDEX(フォロワー推移!$C$2:$C$500,COUNT(フォロワー推移!$A$2:$A$500)) -> 1382
A16: 期間中のフォロワー増加 | B16: =INDEX(フォロワー推移!$B$2:$B$500,COUNT(フォロワー推移!$A$2:$A$500))-フォロワー推移!$B$2 -> 791 | C16: =INDEX(フォロワー推移!$C$2:$C$500,COUNT(フォロワー推移!$A$2:$A$500))-フォロワー推移!$C$2 -> 532
A18: 2. 投稿タイプ別 エンゲージメント率
A19: 区分 | B19: X 投稿数 | C19: X エンゲージメント率 | D19: Threads 投稿数 | E19: Threads エンゲージメント率
A20: テキスト | B20: =COUNTIFS(投稿データ!$C$2:$C$500,"X",投稿データ!$D$2:$D$500,$A20) -> 24 | C20: =IF(SUMIFS(投稿データ!$F$2:$F$500,投稿データ!$C$2:$C$500,"X",投稿データ!$D$2:$D$500,$A20)=0,0,SUMIFS(投稿データ!$L$2:$L$500,投稿データ!$C$2:$C$500,"X",投稿データ!$D$2:$D$500,$A20)/SUMIFS(投稿データ!$F$2:$F$500,投稿データ!$C$2:$C$500,"X",投稿データ!$D$2:$D$500,$A20)) -> 0.01485733 | D20: =COUNTIFS(投稿データ!$C$2:$C$500,"Threads",投稿データ!$D$2:$D$500,$A20) -> 10 | E20: =IF(SUMIFS(投稿データ!$F$2:$F$500,投稿データ!$C$2:$C$500,"Threads",投稿データ!$D$2:$D$500,$A20)=0,0,SUMIFS(投稿データ!$L$2:$L$500,投稿データ!$C$2:$C$500,"Threads",投稿データ!$D$2:$D$500,$A20)/SUMIFS(投稿データ!$F$2:$F$500,投稿データ!$C$2:$C$500,"Threads",投稿データ!$D$2:$D$500,$A20)) -> 0.059729178
A21: 画像 | B21: =COUNTIFS(投稿データ!$C$2:$C$500,"X",投稿データ!$D$2:$D$500,$A21) -> 17 | C21: =IF(SUMIFS(投稿データ!$F$2:$F$500,投稿データ!$C$2:$C$500,"X",投稿データ!$D$2:$D$500,$A21)=0,0,SUMIFS(投稿データ!$L$2:$L$500,投稿データ!$C$2:$C$500,"X",投稿データ!$D$2:$D$500,$A21)/SUMIFS(投稿データ!$F$2:$F$500,投稿データ!$C$2:$C$500,"X",投稿データ!$D$2:$D$500,$A21)) -> 0.025963061 | D21: =COUNTIFS(投稿データ!$C$2:$C$500,"Threads",投稿データ!$D$2:$D$500,$A21) -> 15 | E21: =IF(SUMIFS(投稿データ!$F$2:$F$500,投稿データ!$C$2:$C$500,"Threads",投稿データ!$D$2:$D$500,$A21)=0,0,SUMIFS(投稿データ!$L$2:$L$500,投稿データ!$C$2:$C$500,"Threads",投稿データ!$D$2:$D$500,$A21)/SUMIFS(投稿データ!$F$2:$F$500,投稿データ!$C$2:$C$500,"Threads",投稿データ!$D$2:$D$500,$A21)) -> 0.045262267
A22: 動画 | B22: =COUNTIFS(投稿データ!$C$2:$C$500,"X",投稿データ!$D$2:$D$500,$A22) -> 15 | C22: =IF(SUMIFS(投稿データ!$F$2:$F$500,投稿データ!$C$2:$C$500,"X",投稿データ!$D$2:$D$500,$A22)=0,0,SUMIFS(投稿データ!$L$2:$L$500,投稿データ!$C$2:$C$500,"X",投稿データ!$D$2:$D$500,$A22)/SUMIFS(投稿データ!$F$2:$F$500,投稿データ!$C$2:$C$500,"X",投稿データ!$D$2:$D$500,$A22)) -> 0.032079391 | D22: =COUNTIFS(投稿データ!$C$2:$C$500,"Threads",投稿データ!$D$2:$D$500,$A22) -> 13 | E22: =IF(SUMIFS(投稿データ!$F$2:$F$500,投稿データ!$C$2:$C$500,"Threads",投稿データ!$D$2:$D$500,$A22)=0,0,SUMIFS(投稿データ!$L$2:$L$500,投稿データ!$C$2:$C$500,"Threads",投稿データ!$D$2:$D$500,$A22)/SUMIFS(投稿データ!$F$2:$F$500,投稿データ!$C$2:$C$500,"Threads",投稿データ!$D$2:$D$500,$A22)) -> 0.039666216
A23: リンク | B23: =COUNTIFS(投稿データ!$C$2:$C$500,"X",投稿データ!$D$2:$D$500,$A23) -> 5 | C23: =IF(SUMIFS(投稿データ!$F$2:$F$500,投稿データ!$C$2:$C$500,"X",投稿データ!$D$2:$D$500,$A23)=0,0,SUMIFS(投稿データ!$L$2:$L$500,投稿データ!$C$2:$C$500,"X",投稿データ!$D$2:$D$500,$A23)/SUMIFS(投稿データ!$F$2:$F$500,投稿データ!$C$2:$C$500,"X",投稿データ!$D$2:$D$500,$A23)) -> 0.015877771 | D23: =COUNTIFS(投稿データ!$C$2:$C$500,"Threads",投稿データ!$D$2:$D$500,$A23) -> 4 | E23: =IF(SUMIFS(投稿データ!$F$2:$F$500,投稿データ!$C$2:$C$500,"Threads",投稿データ!$D$2:$D$500,$A23)=0,0,SUMIFS(投稿データ!$L$2:$L$500,投稿データ!$C$2:$C$500,"Threads",投稿データ!$D$2:$D$500,$A23)/SUMIFS(投稿データ!$F$2:$F$500,投稿データ!$C$2:$C$500,"Threads",投稿データ!$D$2:$D$500,$A23)) -> 0.020304569
A25: 3. 曜日別 エンゲージメント率
A26: 区分 | B26: X 投稿数 | C26: X エンゲージメント率 | D26: Threads 投稿数 | E26: Threads エンゲージメント率
A27: 月 | B27: =COUNTIFS(投稿データ!$C$2:$C$500,"X",投稿データ!$N$2:$N$500,$A27) -> 9 | C27: =IF(SUMIFS(投稿データ!$F$2:$F$500,投稿データ!$C$2:$C$500,"X",投稿データ!$N$2:$N$500,$A27)=0,0,SUMIFS(投稿データ!$L$2:$L$500,投稿データ!$C$2:$C$500,"X",投稿データ!$N$2:$N$500,$A27)/SUMIFS(投稿データ!$F$2:$F$500,投稿データ!$C$2:$C$500,"X",投稿データ!$N$2:$N$500,$A27)) -> 0.030323692 | D27: =COUNTIFS(投稿データ!$C$2:$C$500,"Threads",投稿データ!$N$2:$N$500,$A27) -> 4 | E27: =IF(SUMIFS(投稿データ!$F$2:$F$500,投稿データ!$C$2:$C$500,"Threads",投稿データ!$N$2:$N$500,$A27)=0,0,SUMIFS(投稿データ!$L$2:$L$500,投稿データ!$C$2:$C$500,"Threads",投稿データ!$N$2:$N$500,$A27)/SUMIFS(投稿データ!$F$2:$F$500,投稿データ!$C$2:$C$500,"Threads",投稿データ!$N$2:$N$500,$A27)) -> 0.033686837
A28: 火 | B28: =COUNTIFS(投稿データ!$C$2:$C$500,"X",投稿データ!$N$2:$N$500,$A28) -> 7 | C28: =IF(SUMIFS(投稿データ!$F$2:$F$500,投稿データ!$C$2:$C$500,"X",投稿データ!$N$2:$N$500,$A28)=0,0,SUMIFS(投稿データ!$L$2:$L$500,投稿データ!$C$2:$C$500,"X",投稿データ!$N$2:$N$500,$A28)/SUMIFS(投稿データ!$F$2:$F$500,投稿データ!$C$2:$C$500,"X",投稿データ!$N$2:$N$500,$A28)) -> 0.021528738 | D28: =COUNTIFS(投稿データ!$C$2:$C$500,"Threads",投稿データ!$N$2:$N$500,$A28) -> 7 | E28: =IF(SUMIFS(投稿データ!$F$2:$F$500,投稿データ!$C$2:$C$500,"Threads",投稿データ!$N$2:$N$500,$A28)=0,0,SUMIFS(投稿データ!$L$2:$L$500,投稿データ!$C$2:$C$500,"Threads",投稿データ!$N$2:$N$500,$A28)/SUMIFS(投稿データ!$F$2:$F$500,投稿データ!$C$2:$C$500,"Threads",投稿データ!$N$2:$N$500,$A28)) -> 0.056073124
A29: 水 | B29: =COUNTIFS(投稿データ!$C$2:$C$500,"X",投稿データ!$N$2:$N$500,$A29) -> 9 | C29: =IF(SUMIFS(投稿データ!$F$2:$F$500,投稿データ!$C$2:$C$500,"X",投稿データ!$N$2:$N$500,$A29)=0,0,SUMIFS(投稿データ!$L$2:$L$500,投稿データ!$C$2:$C$500,"X",投稿データ!$N$2:$N$500,$A29)/SUMIFS(投稿データ!$F$2:$F$500,投稿データ!$C$2:$C$500,"X",投稿データ!$N$2:$N$500,$A29)) -> 0.025741161 | D29: =COUNTIFS(投稿データ!$C$2:$C$500,"Threads",投稿データ!$N$2:$N$500,$A29) -> 6 | E29: =IF(SUMIFS(投稿データ!$F$2:$F$500,投稿データ!$C$2:$C$500,"Threads",投稿データ!$N$2:$N$500,$A29)=0,0,SUMIFS(投稿データ!$L$2:$L$500,投稿データ!$C$2:$C$500,"Threads",投稿データ!$N$2:$N$500,$A29)/SUMIFS(投稿データ!$F$2:$F$500,投稿データ!$C$2:$C$500,"Threads",投稿データ!$N$2:$N$500,$A29)) -> 0.031294051
A30: 木 | B30: =COUNTIFS(投稿データ!$C$2:$C$500,"X",投稿データ!$N$2:$N$500,$A30) -> 9 | C30: =IF(SUMIFS(投稿データ!$F$2:$F$500,投稿データ!$C$2:$C$500,"X",投稿データ!$N$2:$N$500,$A30)=0,0,SUMIFS(投稿データ!$L$2:$L$500,投稿データ!$C$2:$C$500,"X",投稿データ!$N$2:$N$500,$A30)/SUMIFS(投稿データ!$F$2:$F$500,投稿データ!$C$2:$C$500,"X",投稿データ!$N$2:$N$500,$A30)) -> 0.019728902 | D30: =COUNTIFS(投稿データ!$C$2:$C$500,"Threads",投稿データ!$N$2:$N$500,$A30) -> 3 | E30: =IF(SUMIFS(投稿データ!$F$2:$F$500,投稿データ!$C$2:$C$500,"Threads",投稿データ!$N$2:$N$500,$A30)=0,0,SUMIFS(投稿データ!$L$2:$L$500,投稿データ!$C$2:$C$500,"Threads",投稿データ!$N$2:$N$500,$A30)/SUMIFS(投稿データ!$F$2:$F$500,投稿データ!$C$2:$C$500,"Threads",投稿データ!$N$2:$N$500,$A30)) -> 0.053161724
A31: 金 | B31: =COUNTIFS(投稿データ!$C$2:$C$500,"X",投稿データ!$N$2:$N$500,$A31) -> 9 | C31: =IF(SUMIFS(投稿データ!$F$2:$F$500,投稿データ!$C$2:$C$500,"X",投稿データ!$N$2:$N$500,$A31)=0,0,SUMIFS(投稿データ!$L$2:$L$500,投稿データ!$C$2:$C$500,"X",投稿データ!$N$2:$N$500,$A31)/SUMIFS(投稿データ!$F$2:$F$500,投稿データ!$C$2:$C$500,"X",投稿データ!$N$2:$N$500,$A31)) -> 0.016177327 | D31: =COUNTIFS(投稿データ!$C$2:$C$500,"Threads",投稿データ!$N$2:$N$500,$A31) -> 7 | E31: =IF(SUMIFS(投稿データ!$F$2:$F$500,投稿データ!$C$2:$C$500,"Threads",投稿データ!$N$2:$N$500,$A31)=0,0,SUMIFS(投稿データ!$L$2:$L$500,投稿データ!$C$2:$C$500,"Threads",投稿データ!$N$2:$N$500,$A31)/SUMIFS(投稿データ!$F$2:$F$500,投稿データ!$C$2:$C$500,"Threads",投稿データ!$N$2:$N$500,$A31)) -> 0.041355257
A32: 土 | B32: =COUNTIFS(投稿データ!$C$2:$C$500,"X",投稿データ!$N$2:$N$500,$A32) -> 9 | C32: =IF(SUMIFS(投稿データ!$F$2:$F$500,投稿データ!$C$2:$C$500,"X",投稿データ!$N$2:$N$500,$A32)=0,0,SUMIFS(投稿データ!$L$2:$L$500,投稿データ!$C$2:$C$500,"X",投稿データ!$N$2:$N$500,$A32)/SUMIFS(投稿データ!$F$2:$F$500,投稿データ!$C$2:$C$500,"X",投稿データ!$N$2:$N$500,$A32)) -> 0.026334419 | D32: =COUNTIFS(投稿データ!$C$2:$C$500,"Threads",投稿データ!$N$2:$N$500,$A32) -> 8 | E32: =IF(SUMIFS(投稿データ!$F$2:$F$500,投稿データ!$C$2:$C$500,"Threads",投稿データ!$N$2:$N$500,$A32)=0,0,SUMIFS(投稿データ!$L$2:$L$500,投稿データ!$C$2:$C$500,"Threads",投稿データ!$N$2:$N$500,$A32)/SUMIFS(投稿データ!$F$2:$F$500,投稿データ!$C$2:$C$500,"Threads",投稿データ!$N$2:$N$500,$A32)) -> 0.038150289
A33: 日 | B33: =COUNTIFS(投稿データ!$C$2:$C$500,"X",投稿データ!$N$2:$N$500,$A33) -> 9 | C33: =IF(SUMIFS(投稿データ!$F$2:$F$500,投稿データ!$C$2:$C$500,"X",投稿データ!$N$2:$N$500,$A33)=0,0,SUMIFS(投稿データ!$L$2:$L$500,投稿データ!$C$2:$C$500,"X",投稿データ!$N$2:$N$500,$A33)/SUMIFS(投稿データ!$F$2:$F$500,投稿データ!$C$2:$C$500,"X",投稿データ!$N$2:$N$500,$A33)) -> 0.019882512 | D33: =COUNTIFS(投稿データ!$C$2:$C$500,"Threads",投稿データ!$N$2:$N$500,$A33) -> 7 | E33: =IF(SUMIFS(投稿データ!$F$2:$F$500,投稿データ!$C$2:$C$500,"Threads",投稿データ!$N$2:$N$500,$A33)=0,0,SUMIFS(投稿データ!$L$2:$L$500,投稿データ!$C$2:$C$500,"Threads",投稿データ!$N$2:$N$500,$A33)/SUMIFS(投稿データ!$F$2:$F$500,投稿データ!$C$2:$C$500,"Threads",投稿データ!$N$2:$N$500,$A33)) -> 0.059102266
A35: 4. 時間帯別 エンゲージメント率
A36: 区分 | B36: X 投稿数 | C36: X エンゲージメント率 | D36: Threads 投稿数 | E36: Threads エンゲージメント率
A37: 朝(6-10時) | B37: =COUNTIFS(投稿データ!$C$2:$C$500,"X",投稿データ!$O$2:$O$500,$A37) -> 17 | C37: =IF(SUMIFS(投稿データ!$F$2:$F$500,投稿データ!$C$2:$C$500,"X",投稿データ!$O$2:$O$500,$A37)=0,0,SUMIFS(投稿データ!$L$2:$L$500,投稿データ!$C$2:$C$500,"X",投稿データ!$O$2:$O$500,$A37)/SUMIFS(投稿データ!$F$2:$F$500,投稿データ!$C$2:$C$500,"X",投稿データ!$O$2:$O$500,$A37)) -> 0.01918344 | D37: =COUNTIFS(投稿データ!$C$2:$C$500,"Threads",投稿データ!$O$2:$O$500,$A37) -> 9 | E37: =IF(SUMIFS(投稿データ!$F$2:$F$500,投稿データ!$C$2:$C$500,"Threads",投稿データ!$O$2:$O$500,$A37)=0,0,SUMIFS(投稿データ!$L$2:$L$500,投稿データ!$C$2:$C$500,"Threads",投稿データ!$O$2:$O$500,$A37)/SUMIFS(投稿データ!$F$2:$F$500,投稿データ!$C$2:$C$500,"Threads",投稿データ!$O$2:$O$500,$A37)) -> 0.041549691
A38: 昼(11-14時) | B38: =COUNTIFS(投稿データ!$C$2:$C$500,"X",投稿データ!$O$2:$O$500,$A38) -> 11 | C38: =IF(SUMIFS(投稿データ!$F$2:$F$500,投稿データ!$C$2:$C$500,"X",投稿データ!$O$2:$O$500,$A38)=0,0,SUMIFS(投稿データ!$L$2:$L$500,投稿データ!$C$2:$C$500,"X",投稿データ!$O$2:$O$500,$A38)/SUMIFS(投稿データ!$F$2:$F$500,投稿データ!$C$2:$C$500,"X",投稿データ!$O$2:$O$500,$A38)) -> 0.022840047 | D38: =COUNTIFS(投稿データ!$C$2:$C$500,"Threads",投稿データ!$O$2:$O$500,$A38) -> 10 | E38: =IF(SUMIFS(投稿データ!$F$2:$F$500,投稿データ!$C$2:$C$500,"Threads",投稿データ!$O$2:$O$500,$A38)=0,0,SUMIFS(投稿データ!$L$2:$L$500,投稿データ!$C$2:$C$500,"Threads",投稿データ!$O$2:$O$500,$A38)/SUMIFS(投稿データ!$F$2:$F$500,投稿データ!$C$2:$C$500,"Threads",投稿データ!$O$2:$O$500,$A38)) -> 0.047915598
A39: 夕方(15-18時) | B39: =COUNTIFS(投稿データ!$C$2:$C$500,"X",投稿データ!$O$2:$O$500,$A39) -> 9 | C39: =IF(SUMIFS(投稿データ!$F$2:$F$500,投稿データ!$C$2:$C$500,"X",投稿データ!$O$2:$O$500,$A39)=0,0,SUMIFS(投稿データ!$L$2:$L$500,投稿データ!$C$2:$C$500,"X",投稿データ!$O$2:$O$500,$A39)/SUMIFS(投稿データ!$F$2:$F$500,投稿データ!$C$2:$C$500,"X",投稿データ!$O$2:$O$500,$A39)) -> 0.017200938 | D39: =COUNTIFS(投稿データ!$C$2:$C$500,"Threads",投稿データ!$O$2:$O$500,$A39) -> 3 | E39: =IF(SUMIFS(投稿データ!$F$2:$F$500,投稿データ!$C$2:$C$500,"Threads",投稿データ!$O$2:$O$500,$A39)=0,0,SUMIFS(投稿データ!$L$2:$L$500,投稿データ!$C$2:$C$500,"Threads",投稿データ!$O$2:$O$500,$A39)/SUMIFS(投稿データ!$F$2:$F$500,投稿データ!$C$2:$C$500,"Threads",投稿データ!$O$2:$O$500,$A39)) -> 0.042292239
A40: 夜(19-23時) | B40: =COUNTIFS(投稿データ!$C$2:$C$500,"X",投稿データ!$O$2:$O$500,$A40) -> 21 | C40: =IF(SUMIFS(投稿データ!$F$2:$F$500,投稿データ!$C$2:$C$500,"X",投稿データ!$O$2:$O$500,$A40)=0,0,SUMIFS(投稿データ!$L$2:$L$500,投稿データ!$C$2:$C$500,"X",投稿データ!$O$2:$O$500,$A40)/SUMIFS(投稿データ!$F$2:$F$500,投稿データ!$C$2:$C$500,"X",投稿データ!$O$2:$O$500,$A40)) -> 0.028823232 | D40: =COUNTIFS(投稿データ!$C$2:$C$500,"Threads",投稿データ!$O$2:$O$500,$A40) -> 19 | E40: =IF(SUMIFS(投稿データ!$F$2:$F$500,投稿データ!$C$2:$C$500,"Threads",投稿データ!$O$2:$O$500,$A40)=0,0,SUMIFS(投稿データ!$L$2:$L$500,投稿データ!$C$2:$C$500,"Threads",投稿データ!$O$2:$O$500,$A40)/SUMIFS(投稿データ!$F$2:$F$500,投稿データ!$C$2:$C$500,"Threads",投稿データ!$O$2:$O$500,$A40)) -> 0.050218514
A41: 深夜(0-5時) | B41: =COUNTIFS(投稿データ!$C$2:$C$500,"X",投稿データ!$O$2:$O$500,$A41) -> 3 | C41: =IF(SUMIFS(投稿データ!$F$2:$F$500,投稿データ!$C$2:$C$500,"X",投稿データ!$O$2:$O$500,$A41)=0,0,SUMIFS(投稿データ!$L$2:$L$500,投稿データ!$C$2:$C$500,"X",投稿データ!$O$2:$O$500,$A41)/SUMIFS(投稿データ!$F$2:$F$500,投稿データ!$C$2:$C$500,"X",投稿データ!$O$2:$O$500,$A41)) -> 0.020715404 | D41: =COUNTIFS(投稿データ!$C$2:$C$500,"Threads",投稿データ!$O$2:$O$500,$A41) -> 1 | E41: =IF(SUMIFS(投稿データ!$F$2:$F$500,投稿データ!$C$2:$C$500,"Threads",投稿データ!$O$2:$O$500,$A41)=0,0,SUMIFS(投稿データ!$L$2:$L$500,投稿データ!$C$2:$C$500,"Threads",投稿データ!$O$2:$O$500,$A41)/SUMIFS(投稿データ!$F$2:$F$500,投稿データ!$C$2:$C$500,"Threads",投稿データ!$O$2:$O$500,$A41)) -> 0.020030045
A43: 5. エンゲージメント率 TOP5 投稿(両SNS合算)
A44: 順位 | B44: 投稿日 | C44: SNS | D44: 投稿タイプ | E44: 内容メモ | F44: インプレッション | G44: エンゲージメント率
A45: 1 | B45: =IFERROR(INDEX(投稿データ!$A$2:$A$500,MATCH(LARGE(投稿データ!$P$2:$P$500,1),投稿データ!$P$2:$P$500,0)),"") -> 46231 | C45: =IFERROR(INDEX(投稿データ!$C$2:$C$500,MATCH(LARGE(投稿データ!$P$2:$P$500,1),投稿データ!$P$2:$P$500,0)),"") -> Threads | D45: =IFERROR(INDEX(投稿データ!$D$2:$D$500,MATCH(LARGE(投稿データ!$P$2:$P$500,1),投稿データ!$P$2:$P$500,0)),"") -> テキスト | E45: =IFERROR(INDEX(投稿データ!$E$2:$E$500,MATCH(LARGE(投稿データ!$P$2:$P$500,1),投稿データ!$P$2:$P$500,0)),"") -> 今日のひとこと | F45: =IFERROR(INDEX(投稿データ!$F$2:$F$500,MATCH(LARGE(投稿データ!$P$2:$P$500,1),投稿データ!$P$2:$P$500,0)),"") -> 1977 | G45: =IFERROR(INDEX(投稿データ!$M$2:$M$500,MATCH(LARGE(投稿データ!$P$2:$P$500,1),投稿データ!$P$2:$P$500,0)),"") -> 0.084471421
...

Sheet 投稿データ
A1: 投稿日 | B1: 時刻 | C1: SNS | D1: 投稿タイプ | E1: 内容メモ | F1: インプレッション | G1: いいね | H1: リポスト | I1: 返信 | J1: 引用 | K1: リンククリック | L1: エンゲージメント合計 | M1: エンゲージメント率 | N1: 曜日 | O1: 時間帯 | P1: 順位用(自動)
A2: 46204 | B2: 0.5 | C2: X | D2: テキスト | E2: アンケート | F2: 1671 | G2: 12 | H2: 2 | I2: 1 | J2: 0 | K2: 1 | L2: =IF(A2="","",SUM(G2:K2)) -> 16 | M2: =IF(A2="","",IF(F2=0,0,L2/F2)) -> 0.0095751047 | N2: =IF(A2="","",CHOOSE(WEEKDAY(A2,2),"月","火","水","木","金","土","日")) -> 水 | O2: =IF(B2="","",IF(HOUR(B2)<6,"深夜(0-5時)",IF(HOUR(B2)<11,"朝(6-10時)",IF(HOUR(B2)<15,"昼(11-14時)",IF(HOUR(B2)<19,"夕方(15-18時)","夜(19-23時)"))))) -> 昼(11-14時) | P2: =IF(M2="","",M2+ROW()/1000000000) -> 0.0095751067
A3: 46205 | B3: 0.83333333 | C3: X | D3: 画像 | E3: 業界ニュースへのコメント | F3: 2767 | G3: 64 | H3: 14 | I3: 9 | J3: 4 | K3: 5 | L3: =IF(A3="","",SUM(G3:K3)) -> 96 | M3: =IF(A3="","",IF(F3=0,0,L3/F3)) -> 0.034694615 | N3: =IF(A3="","",CHOOSE(WEEKDAY(A3,2),"月","火","水","木","金","土","日")) -> 木 | O3: =IF(B3="","",IF(HOUR(B3)<6,"深夜(0-5時)",IF(HOUR(B3)<11,"朝(6-10時)",IF(HOUR(B3)<15,"昼(11-14時)",IF(HOUR(B3)<19,"夕方(15-18時)","夜(19-23時)"))))) -> 夜(19-23時) | P3: =IF(M3="","",M3+ROW()/1000000000) -> 0.034694618
A4: 46206 | B4: 0.71875 | C4: X | D4: 画像 | E4: アンケート | F4: 1743 | G4: 29 | H4: 6 | I4: 4 | J4: 1 | K4: 2 | L4: =IF(A4="","",SUM(G4:K4)) -> 42 | M4: =IF(A4="","",IF(F4=0,0,L4/F4)) -> 0.024096386 | N4: =IF(A4="","",CHOOSE(WEEKDAY(A4,2),"月","火","水","木","金","土","日")) -> 金 | O4: =IF(B4="","",IF(HOUR(B4)<6,"深夜(0-5時)",IF(HOUR(B4)<11,"朝(6-10時)",IF(HOUR(B4)<15,"昼(11-14時)",IF(HOUR(B4)<19,"夕方(15-18時)","夜(19-23時)"))))) -> 夕方(15-18時) | P4: =IF(M4="","",M4+ROW()/1000000000) -> 0.02409639
A5: 46206 | B5: 0.88541667 | C5: Threads | D5: 動画 | E5: ユーザーの声 | F5: 854 | G5: 30 | H5: 3 | I5: 10 | J5: 1 | K5: 0 | L5: =IF(A5="","",SUM(G5:K5)) -> 44 | M5: =IF(A5="","",IF(F5=0,0,L5/F5)) -> 0.051522248 | N5: =IF(A5="","",CHOOSE(WEEKDAY(A5,2),"月","火","水","木","金","土","日")) -> 金 | O5: =IF(B5="","",IF(HOUR(B5)<6,"深夜(0-5時)",IF(HOUR(B5)<11,"朝(6-10時)",IF(HOUR(B5)<15,"昼(11-14時)",IF(HOUR(B5)<19,"夕方(15-18時)","夜(19-23時)"))))) -> 夜(19-23時) | P5: =IF(M5="","",M5+ROW()/1000000000) -> 0.051522253
A6: 46207 | B6: 0.875 | C6: X | D6: テキスト | E6: ユーザーの声 | F6: 2121 | G6: 37 | H6: 8 | I6: 5 | J6: 2 | K6: 3 | L6: =IF(A6="","",SUM(G6:K6)) -> 55 | M6: =IF(A6="","",IF(F6=0,0,L6/F6)) -> 0.025931165 | N6: =IF(A6="","",CHOOSE(WEEKDAY(A6,2),"月","火","水","木","金","土","日")) -> 土 | O6: =IF(B6="","",IF(HOUR(B6)<6,"深夜(0-5時)",IF(HOUR(B6)<11,"朝(6-10時)",IF(HOUR(B6)<15,"昼(11-14時)",IF(HOUR(B6)<19,"夕方(15-18時)","夜(19-23時)"))))) -> 夜(19-23時) | P6: =IF(M6="","",M6+ROW()/1000000000) -> 0.025931171
A7: 46207 | B7: 0.98958333 | C7: Threads | D7: 画像 | E7: アンケート | F7: 991 | G7: 27 | H7: 3 | I7: 9 | J7: 1 | K7: 0 | L7: =IF(A7="","",SUM(G7:K7)) -> 40 | M7: =IF(A7="","",IF(F7=0,0,L7/F7)) -> 0.040363269 | N7: =IF(A7="","",CHOOSE(WEEKDAY(A7,2),"月","火","水","木","金","土","日")) -> 土 | O7: =IF(B7="","",IF(HOUR(B7)<6,"深夜(0-5時)",IF(HOUR(B7)<11,"朝(6-10時)",IF(HOUR(B7)<15,"昼(11-14時)",IF(HOUR(B7)<19,"夕方(15-18時)","夜(19-23時)"))))) -> 夜(19-23時) | P7: =IF(M7="","",M7+ROW()/1000000000) -> 0.040363276
A8: 46208 | B8: 0.94791667 | C8: X | D8: テキスト | E8: よくある質問への回答 | F8: 2328 | G8: 38 | H8: 8 | I8: 5 | J8: 2 | K8: 3 | L8: =IF(A8="","",SUM(G8:K8)) -> 56 | M8: =IF(A8="","",IF(F8=0,0,L8/F8)) -> 0.024054983 | N8: =IF(A8="","",CHOOSE(WEEKDAY(A8,2),"月","火","水","木","金","土","日")) -> 日 | O8: =IF(B8="","",IF(HOUR(B8)<6,"深夜(0-5時)",IF(HOUR(B8)<11,"朝(6-10時)",IF(HOUR(B8)<15,"昼(11-14時)",IF(HOUR(B8)<19,"夕方(15-18時)","夜(19-23時)"))))) -> 夜(19-23時) | P8: =IF(M8="","",M8+ROW()/1000000000) -> 0.024054991
A9: 46208 | B9: 0.89583333 | C9: Threads | D9: 動画 | E9: 新商品の紹介 | F9: 1391 | G9: 41 | H9: 5 | I9: 14 | J9: 2 | K9: 0 | L9: =IF(A9="","",SUM(G9:K9)) -> 62 | M9: =IF(A9="","",IF(F9=0,0,L9/F9)) -> 0.04457225 | N9: =IF(A9="","",CHOOSE(WEEKDAY(A9,2),"月","火","水","木","金","土","日")) -> 日 | O9: =IF(B9="","",IF(HOUR(B9)<6,"深夜(0-5時)",IF(HOUR(B9)<11,"朝(6-10時)",IF(HOUR(B9)<15,"昼(11-14時)",IF(HOUR(B9)<19,"夕方(15-18時)","夜(19-23時)"))))) -> 夜(19-23時) | P9: =IF(M9="","",M9+ROW()/1000000000) -> 0.044572259
A10: 46209 | B10: 0.94791667 | C10: X | D10: 画像 | E10: 新商品の紹介 | F10: 3019 | G10: 74 | H10: 16 | I10: 10 | J10: 4 | K10: 5 | L10: =IF(A10="","",SUM(G10:K10)) -> 109 | M10: =IF(A10="","",IF(F10=0,0,L10/F10)) -> 0.03610467 | N10: =IF(A10="","",CHOOSE(WEEKDAY(A10,2),"月","火","水","木","金","土","日")) -> 月 | O10: =IF(B10="","",IF(HOUR(B10)<6,"深夜(0-5時)",IF(HOUR(B10)<11,"朝(6-10時)",IF(HOUR(B10)<15,"昼(11-14時)",IF(HOUR(B10)<19,"夕方(15-18時)","夜(19-23時)"))))) -> 夜(19-23時) | P10: =IF(M10="","",M10+ROW()/1000000000) -> 0.03610468
A11: 46210 | B11: 0.91666667 | C11: X | D11: 動画 | E11: アンケート | F11: 2526 | G11: 66 | H11: 14 | I11: 9 | J11: 4 | K11: 5 | L11: =IF(A11="","",SUM(G11:K11)) -> 98 | M11: =IF(A11="","",IF(F11=0,0,L11/F11)) -> 0.038796516 | N11: =IF(A11="","",CHOOSE(WEEKDAY(A11,2),"月","火","水","木","金","土","日")) -> 火 | O11: =IF(B11="","",IF(HOUR(B11)<6,"深夜(0-5時)",IF(HOUR(B11)<11,"朝(6-10時)",IF(HOUR(B11)<15,"昼(11-14時)",IF(HOUR(B11)<19,"夕方(15-18時)","夜(19-23時)"))))) -> 夜(19-23時) | P11: =IF(M11="","",M11+ROW()/1000000000) -> 0.038796527
A12: 46211 | B12: 0.36458333 | C12: X | D12: 画像 | E12: ノウハウ共有 | F12: 3198 | G12: 38 | H12: 8 | I12: 5 | J12: 2 | K12: 3 | L12: =IF(A12="","",SUM(G12:K12)) -> 56 | M12: =IF(A12="","",IF(F12=0,0,L12/F12)) -> 0.017510944 | N12: =IF(A12="","",CHOOSE(WEEKDAY(A12,2),"月","火","水","木","金","土","日")) -> 水 | O12: =IF(B12="","",IF(HOUR(B12)<6,"深夜(0-5時)",IF(HOUR(B12)<11,"朝(6-10時)",IF(HOUR(B12)<15,"昼(11-14時)",IF(HOUR(B12)<19,"夕方(15-18時)","夜(19-23時)"))))) -> 朝(6-10時) | P12: =IF(M12="","",M12+ROW()/1000000000) -> 0.017510956
A13: 46211 | B13: 0.38541667 | C13: Threads | D13: テキスト | E13: ノウハウ共有 | F13: 1102 | G13: 43 | H13: 5 | I13: 15 | J13: 2 | K13: 0 | L13: =IF(A13="","",SUM(G13:K13)) -> 65 | M13: =IF(A13="","",IF(F13=0,0,L13/F13)) -> 0.058983666 | N13: =IF(A13="","",CHOOSE(WEEKDAY(A13,2),"月","火","水","木","金","土","日")) -> 水 | O13: =IF(B13="","",IF(HOUR(B13)<6,"深夜(0-5時)",IF(HOUR(B13)<11,"朝(6-10時)",IF(HOUR(B13)<15,"昼(11-14時)",IF(HOUR(B13)<19,"夕方(15-18時)","夜(19-23時)"))))) -> 朝(6-10時) | P13: =IF(M13="","",M13+ROW()/1000000000) -> 0.058983679
... A104: 46265 | B104: 0.9375 | C104: Threads | D104: 動画 | E104: ノウハウ共有 | F104: 1060 | G104: 27 | H104: 3 | I104: 9 | J104: 1 | K104: 0 | L104: =IF(A104="","",SUM(G104:K104)) -> 40 | M104: =IF(A104="","",IF(F104=0,0,L104/F104)) -> 0.037735849 | N104: =IF(A104="","",CHOOSE(WEEKDAY(A104,2),"月","火","水","木","金","土","日")) -> 月 | O104: =IF(B104="","",IF(HOUR(B104)<6,"深夜(0-5時)",IF(HOUR(B104)<11,"朝(6-10時)",IF(HOUR(B104)<15,"昼(11-14時)",IF(HOUR(B104)<19,"夕方(15-18時)","夜(19-23時)"))))) -> 夜(19-23時) | P104: =IF(M104="","",M104+ROW()/1000000000) -> 0.037735953
L105: =IF(A105="","",SUM(G105:K105)) | M105: =IF(A105="","",IF(F105=0,0,L105/F105)) | N105: =IF(A105="","",CHOOSE(WEEKDAY(A105,2),"月","火","水","木","金","土","日")) | O105: =IF(B105="","",IF(HOUR(B105)<6,"深夜(0-5時)",IF(HOUR(B105)<11,"朝(6-10時)",IF(HOUR(B105)<15,"昼(11-14時)",IF(HOUR(B105)<19,"夕方(15-18時)","夜(19-23時)"))))) | P105: =IF(M105="","",M105+ROW()/1000000000)
L106: =IF(A106="","",SUM(G106:K106)) | M106: =IF(A106="","",IF(F106=0,0,L106/F106)) | N106: =IF(A106="","",CHOOSE(WEEKDAY(A106,2),"月","火","水","木","金","土","日")) | O106: =IF(B106="","",IF(HOUR(B106)<6,"深夜(0-5時)",IF(HOUR(B106)<11,"朝(6-10時)",IF(HOUR(B106)<15,"昼(11-14時)",IF(HOUR(B106)<19,"夕方(15-18時)","夜(19-23時)"))))) | P106: =IF(M106="","",M106+ROW()/1000000000)
L107: =IF(A107="","",SUM(G107:K107)) | M107: =IF(A107="","",IF(F107=0,0,L107/F107)) | N107: =IF(A107="","",CHOOSE(WEEKDAY(A107,2),"月","火","水","木","金","土","日")) | O107: =IF(B107="","",IF(HOUR(B107)<6,"深夜(0-5時)",IF(HOUR(B107)<11,"朝(6-10時)",IF(HOUR(B107)<15,"昼(11-14時)",IF(HOUR(B107)<19,"夕方(15-18時)","夜(19-23時)"))))) | P107: =IF(M107="","",M107+ROW()/1000000000)
L108: =IF(A108="","",SUM(G108:K108)) | M108: =IF(A108="","",IF(F108=0,0,L108/F108)) | N108: =IF(A108="","",CHOOSE(WEEKDAY(A108,2),"月","火","水","木","金","土","日")) | O108: =IF(B108="","",IF(HOUR(B108)<6,"深夜(0-5時)",IF(HOUR(B108)<11,"朝(6-10時)",IF(HOUR(B108)<15,"昼(11-14時)",IF(HOUR(B108)<19,"夕方(15-18時)","夜(19-23時)"))))) | P108: =IF(M108="","",M108+ROW()/1000000000)
L109: =IF(A109="","",SUM(G109:K109)) | M109: =IF(A109="","",IF(F109=0,0,L109/F109)) | N109: =IF(A109="","",CHOOSE(WEEKDAY(A109,2),"月","火","水","木","金","土","日")) | O109: =IF(B109="","",IF(HOUR(B109)<6,"深夜(0-5時)",IF(HOUR(B109)<11,"朝(6-10時)",IF(HOUR(B109)<15,"昼(11-14時)",IF(HOUR(B109)<19,"夕方(15-18時)","夜(19-23時)"))))) | P109: =IF(M109="","",M109+ROW()/1000000000)
L110: =IF(A110="","",SUM(G110:K110)) | M110: =IF(A110="","",IF(F110=0,0,L110/F110)) | N110: =IF(A110="","",CHOOSE(WEEKDAY(A110,2),"月","火","水","木","金","土","日")) | O110: =IF(B110="","",IF(HOUR(B110)<6,"深夜(0-5時)",IF(HOUR(B110)<11,"朝(6-10時)",IF(HOUR(B110)<15,"昼(11-14時)",IF(HOUR(B110)<19,"夕方(15-18時)","夜(19-23時)"))))) | P110: =IF(M110="","",M110+ROW()/1000000000)
L111: =IF(A111="","",SUM(G111:K111)) | M111: =IF(A111="","",IF(F111=0,0,L111/F111)) | N111: =IF(A111="","",CHOOSE(WEEKDAY(A111,2),"月","火","水","木","金","土","日")) | O111: =IF(B111="","",IF(HOUR(B111)<6,"深夜(0-5時)",IF(HOUR(B111)<11,"朝(6-10時)",IF(HOUR(B111)<15,"昼(11-14時)",IF(HOUR(B111)<19,"夕方(15-18時)","夜(19-23時)"))))) | P111: =IF(M111="","",M111+ROW()/1000000000)
L112: =IF(A112="","",SUM(G112:K112)) | M112: =IF(A112="","",IF(F112=0,0,L112/F112)) | N112: =IF(A112="","",CHOOSE(WEEKDAY(A112,2),"月","火","水","木","金","土","日")) | O112: =IF(B112="","",IF(HOUR(B112)<6,"深夜(0-5時)",IF(HOUR(B112)<11,"朝(6-10時)",IF(HOUR(B112)<15,"昼(11-14時)",IF(HOUR(B112)<19,"夕方(15-18時)","夜(19-23時)"))))) | P112: =IF(M112="","",M112+ROW()/1000000000)
L113: =IF(A113="","",SUM(G113:K113)) | M113: =IF(A113="","",IF(F113=0,0,L113/F113)) | N113: =IF(A113="","",CHOOSE(WEEKDAY(A113,2),"月","火","水","木","金","土","日")) | O113: =IF(B113="","",IF(HOUR(B113)<6,"深夜(0-5時)",IF(HOUR(B113)<11,"朝(6-10時)",IF(HOUR(B113)<15,"昼(11-14時)",IF(HOUR(B113)<19,"夕方(15-18時)","夜(19-23時)"))))) | P113: =IF(M113="","",M113+ROW()/1000000000)
L114: =IF(A114="","",SUM(G114:K114)) | M114: =IF(A114="","",IF(F114=0,0,L114/F114)) | N114: =IF(A114="","",CHOOSE(WEEKDAY(A114,2),"月","火","水","木","金","土","日")) | O114: =IF(B114="","",IF(HOUR(B114)<6,"深夜(0-5時)",IF(HOUR(B114)<11,"朝(6-10時)",IF(HOUR(B114)<15,"昼(11-14時)",IF(HOUR(B114)<19,"夕方(15-18時)","夜(19-23時)"))))) | P114: =IF(M114="","",M114+ROW()/1000000000)
L115: =IF(A115="","",SUM(G115:K115)) | M115: =IF(A115="","",IF(F115=0,0,L115/F115)) | N115: =IF(A115="","",CHOOSE(WEEKDAY(A115,2),"月","火","水","木","金","土","日")) | O115: =IF(B115="","",IF(HOUR(B115)<6,"深夜(0-5時)",IF(HOUR(B115)<11,"朝(6-10時)",IF(HOUR(B115)<15,"昼(11-14時)",IF(HOUR(B115)<19,"夕方(15-18時)","夜(19-23時)"))))) | P115: =IF(M115="","",M115+ROW()/1000000000)
L116: =IF(A116="","",SUM(G116:K116)) | M116: =IF(A116="","",IF(F116=0,0,L116/F116)) | N116: =IF(A116="","",CHOOSE(WEEKDAY(A116,2),"月","火","水","木","金","土","日")) | O116: =IF(B116="","",IF(HOUR(B116)<6,"深夜(0-5時)",IF(HOUR(B116)<11,"朝(6-10時)",IF(HOUR(B116)<15,"昼(11-14時)",IF(HOUR(B116)<19,"夕方(15-18時)","夜(19-23時)"))))) | P116: =IF(M116="","",M116+ROW()/1000000000)
... L500: =IF(A500="","",SUM(G500:K500)) | M500: =IF(A500="","",IF(F500=0,0,L500/F500)) | N500: =IF(A500="","",CHOOSE(WEEKDAY(A500,2),"月","火","水","木","金","土","日")) | O500: =IF(B500="","",IF(HOUR(B500)<6,"深夜(0-5時)",IF(HOUR(B500)<11,"朝(6-10時)",IF(HOUR(B500)<15,"昼(11-14時)",IF(HOUR(B500)<19,"夕方(15-18時)","夜(19-23時)"))))) | P500: =IF(M500="","",M500+ROW()/1000000000)

Sheet フォロワー推移
A1: 日付 | B1: X フォロワー | C1: Threads フォロワー | D1: X 増減 | E1: Threads 増減
A2: 46201 | B2: 3200 | C2: 850 | D2: - | E2: -
A3: 46208 | B3: 3264 | C3: 934 | D3: =B3-B2 -> 64 | E3: =C3-C2 -> 84
A4: 46215 | B4: 3370 | C4: 1006 | D4: =B4-B3 -> 106 | E4: =C4-C3 -> 72
A5: 46222 | B5: 3461 | C5: 1044 | D5: =B5-B4 -> 91 | E5: =C5-C4 -> 38
A6: 46229 | B6: 3523 | C6: 1080 | D6: =B6-B5 -> 62 | E6: =C6-C5 -> 36
A7: 46236 | B7: 3625 | C7: 1150 | D7: =B7-B6 -> 102 | E7: =C7-C6 -> 70
A8: 46243 | B8: 3731 | C8: 1186 | D8: =B8-B7 -> 106 | E8: =C8-C7 -> 36
A9: 46250 | B9: 3806 | C9: 1259 | D9: =B9-B8 -> 75 | E9: =C9-C8 -> 73
A10: 46257 | B10: 3905 | C10: 1326 | D10: =B10-B9 -> 99 | E10: =C10-C9 -> 67
A11: 46264 | B11: 3991 | C11: 1382 | D11: =B11-B10 -> 86 | E11: =C11-C10 -> 56
