Workbook

Sheet 投稿一覧
A1: 投稿 | B1: カテゴリ | C1: 投稿からの経過 | D1: 閲覧数 | E1: いいね | F1: 返信 | G1: 再投稿 | H1: シェア | I1: 反応合計 | J1: いいね率 | K1: 反応率
A2: 沖縄限定ガチャシリーズ | B2: ガチャ | C2: 2週間 | D2: 4374 | E2: 42 | F2: 0 | G2: 0 | H2: 0 | I2: =SUM(E2:H2) -> 42 | J2: =IF(D2=0,0,E2/D2) -> 0.0096021948 | K2: =IF(D2=0,0,I2/D2) -> 0.0096021948
A3: 人気食堂シリーズ 糸満市座波 魚太郎 | B3: グルメ | C3: 5週間 | D3: 3262 | E3: 25 | F3: 0 | G3: 1 | H3: 0 | I3: =SUM(E3:H3) -> 26 | J3: =IF(D3=0,0,E3/D3) -> 0.0076640098 | K3: =IF(D3=0,0,I3/D3) -> 0.0079705702
A4: 沖縄弁当屋シリーズ | B4: グルメ | C4: 1週間 | D4: 3236 | E4: 11 | F4: 0 | G4: 0 | H4: 0 | I4: =SUM(E4:H4) -> 11 | J4: =IF(D4=0,0,E4/D4) -> 0.0033992583 | K4: =IF(D4=0,0,I4/D4) -> 0.0033992583
A5: 沖縄限定お店シリーズ(GRINGO TACOS) | B5: お店 | C5: 4週間 | D5: 1496 | E5: 3 | F5: 1 | G5: 1 | H5: 0 | I5: =SUM(E5:H5) -> 5 | J5: =IF(D5=0,0,E5/D5) -> 0.0020053476 | K5: =IF(D5=0,0,I5/D5) -> 0.003342246
A6: 沖縄限定お店 おしゃれな店内、2Fには… | B6: お店 | C6: 3週間 | D6: 1408 | E6: 22 | F6: 0 | G6: 0 | H6: 0 | I6: =SUM(E6:H6) -> 22 | J6: =IF(D6=0,0,E6/D6) -> 0.015625 | K6: =IF(D6=0,0,I6/D6) -> 0.015625
A7: 沖縄 伝統芸能シリーズ | B7: 伝統芸能 | C7: 4週間 | D7: 1130 | E7: 29 | F7: 0 | G7: 1 | H7: 0 | I7: =SUM(E7:H7) -> 30 | J7: =IF(D7=0,0,E7/D7) -> 0.025663717 | K7: =IF(D7=0,0,I7/D7) -> 0.026548673
A8: 沖縄限定お店シリーズ | B8: お店 | C8: 5週間 | D8: 1124 | E8: 14 | F8: 0 | G8: 0 | H8: 0 | I8: =SUM(E8:H8) -> 14 | J8: =IF(D8=0,0,E8/D8) -> 0.012455516 | K8: =IF(D8=0,0,I8/D8) -> 0.012455516
A9: 沖縄限定路上販売シリーズ | B9: レア・珍スポット | C9: 1週間 | D9: 942 | E9: 6 | F9: 0 | G9: 0 | H9: 0 | I9: =SUM(E9:H9) -> 6 | J9: =IF(D9=0,0,E9/D9) -> 0.0063694268 | K9: =IF(D9=0,0,I9/D9) -> 0.0063694268
A10: レア自動販売シリーズ ドライブ中にお漏らし | B10: レア・珍スポット | C10: 3週間 | D10: 886 | E10: 11 | F10: 1 | G10: 0 | H10: 0 | I10: =SUM(E10:H10) -> 12 | J10: =IF(D10=0,0,E10/D10) -> 0.01241535 | K10: =IF(D10=0,0,I10/D10) -> 0.013544018
A11: レアなテーマパークシリーズ | B11: レア・珍スポット | C11: 5週間 | D11: 788 | E11: 7 | F11: 3 | G11: 0 | H11: 0 | I11: =SUM(E11:H11) -> 10 | J11: =IF(D11=0,0,E11/D11) -> 0.0088832487 | K11: =IF(D11=0,0,I11/D11) -> 0.012690355
A12: 沖縄 伝統芸能シリーズ | B12: 伝統芸能 | C12: 4週間 | D12: 689 | E12: 6 | F12: 0 | G12: 0 | H12: 0 | I12: =SUM(E12:H12) -> 6 | J12: =IF(D12=0,0,E12/D12) -> 0.0087082729 | K12: =IF(D12=0,0,I12/D12) -> 0.0087082729
A13: 沖縄限定レアたまごシリーズ | B13: グルメ | C13: 4日 | D13: 677 | E13: 1 | F13: 0 | G13: 0 | H13: 0 | I13: =SUM(E13:H13) -> 1 | J13: =IF(D13=0,0,E13/D13) -> 0.0014771049 | K13: =IF(D13=0,0,I13/D13) -> 0.0014771049
... A15: 沖縄限定居酒屋シリーズ | B15: グルメ | C15: 1日 | D15: 287 | E15: 0 | F15: 1 | G15: 0 | H15: 0 | I15: =SUM(E15:H15) -> 1 | J15: =IF(D15=0,0,E15/D15) -> 0 | K15: =IF(D15=0,0,I15/D15) -> 0.0034843206
A16: 合計 | D16: =SUM(D2:D15) -> 20476 | E16: =SUM(E2:E15) -> 177 | F16: =SUM(F2:F15) -> 7 | G16: =SUM(G2:G15) -> 3 | H16: =SUM(H2:H15) -> 0 | I16: =SUM(I2:I15) -> 187 | J16: =IF(D16=0,0,E16/D16) -> 0.0086442665 | K16: =IF(D16=0,0,I16/D16) -> 0.0091326431
A18: 出典: Threads インサイト画面(ユーザー提供のスクリーンショット、2026/09/24 時点)
A19: ※ 閲覧数上位12件(90日間)+最新投稿2件。カテゴリは投稿タイトルから分類。青字=転記した値、黒字=計算式。

Sheet カテゴリ別
A1: カテゴリ別の成績
A3: カテゴリ | B3: 投稿数 | C3: 閲覧数合計 | D3: 1投稿あたり閲覧数 | E3: いいね合計 | F3: いいね率 | G3: 返信合計
A4: ガチャ | B4: =COUNTIFS(投稿一覧!$B$2:$B$15,$A4) -> 1 | C4: =SUMIFS(投稿一覧!$D$2:$D$15,投稿一覧!$B$2:$B$15,$A4) -> 4374 | D4: =IF(B4=0,0,C4/B4) -> 4374 | E4: =SUMIFS(投稿一覧!$E$2:$E$15,投稿一覧!$B$2:$B$15,$A4) -> 42 | F4: =IF(C4=0,0,E4/C4) -> 0.0096021948 | G4: =SUMIFS(投稿一覧!$F$2:$F$15,投稿一覧!$B$2:$B$15,$A4) -> 0
A5: グルメ | B5: =COUNTIFS(投稿一覧!$B$2:$B$15,$A5) -> 4 | C5: =SUMIFS(投稿一覧!$D$2:$D$15,投稿一覧!$B$2:$B$15,$A5) -> 7462 | D5: =IF(B5=0,0,C5/B5) -> 1865.5 | E5: =SUMIFS(投稿一覧!$E$2:$E$15,投稿一覧!$B$2:$B$15,$A5) -> 37 | F5: =IF(C5=0,0,E5/C5) -> 0.0049584562 | G5: =SUMIFS(投稿一覧!$F$2:$F$15,投稿一覧!$B$2:$B$15,$A5) -> 1
A6: お店 | B6: =COUNTIFS(投稿一覧!$B$2:$B$15,$A6) -> 4 | C6: =SUMIFS(投稿一覧!$D$2:$D$15,投稿一覧!$B$2:$B$15,$A6) -> 4205 | D6: =IF(B6=0,0,C6/B6) -> 1051.25 | E6: =SUMIFS(投稿一覧!$E$2:$E$15,投稿一覧!$B$2:$B$15,$A6) -> 39 | F6: =IF(C6=0,0,E6/C6) -> 0.009274673 | G6: =SUMIFS(投稿一覧!$F$2:$F$15,投稿一覧!$B$2:$B$15,$A6) -> 2
A7: 伝統芸能 | B7: =COUNTIFS(投稿一覧!$B$2:$B$15,$A7) -> 2 | C7: =SUMIFS(投稿一覧!$D$2:$D$15,投稿一覧!$B$2:$B$15,$A7) -> 1819 | D7: =IF(B7=0,0,C7/B7) -> 909.5 | E7: =SUMIFS(投稿一覧!$E$2:$E$15,投稿一覧!$B$2:$B$15,$A7) -> 35 | F7: =IF(C7=0,0,E7/C7) -> 0.019241341 | G7: =SUMIFS(投稿一覧!$F$2:$F$15,投稿一覧!$B$2:$B$15,$A7) -> 0
A8: レア・珍スポット | B8: =COUNTIFS(投稿一覧!$B$2:$B$15,$A8) -> 3 | C8: =SUMIFS(投稿一覧!$D$2:$D$15,投稿一覧!$B$2:$B$15,$A8) -> 2616 | D8: =IF(B8=0,0,C8/B8) -> 872 | E8: =SUMIFS(投稿一覧!$E$2:$E$15,投稿一覧!$B$2:$B$15,$A8) -> 24 | F8: =IF(C8=0,0,E8/C8) -> 0.0091743119 | G8: =SUMIFS(投稿一覧!$F$2:$F$15,投稿一覧!$B$2:$B$15,$A8) -> 4

Sheet オーディエンス
A1: オーディエンス(直近30日: 8/26〜9/24)
A3: 概要
A4: 指標 | B4: 値
A5: 閲覧数 | B5: 28830
A6: 閲覧者 | B6: 20520
A7: 閲覧者のうちフォロワー | B7: 12
A8: 純フォロワー増 | B8: 12
A9: 閲覧数の前期比 | B9: 3.975
A10: 閲覧者の前期比 | B10: 3.563
A12: 年齢
A13: 年齢 | B13: 割合
A14: 13-17 | B14: 0.0011
A15: 18-24 | B15: 0.0626
A16: 25-34 | B16: 0.304
A17: 35-44 | B17: 0.3361
A18: 45-54 | B18: 0.2114
A19: 55-64 | B19: 0.0723
A20: 65+ | B20: 0.0126
A22: 性別
A23: 性別 | B23: 割合
A24: 女性 | B24: 0.3378
A25: 男性 | B25: 0.1597
A26: その他・不明 | B26: 0.5025
A28: 市区町村(上位5)
A29: 市区町村 | B29: 割合
A30: 那覇市 | B30: 0.0986
A31: 沖縄市 | B31: 0.0765
A32: 宜野湾市 | B32: 0.0472
A33: 島尻郡 | B33: 0.0328
A34: 浦添市 | B34: 0.0321
A36: 国・地域(上位5)
A37: 国・地域 | B37: 割合
A38: 日本 | B38: 0.7773
A39: 台湾 | B39: 0.0033
A40: 香港 | B40: 0.0013
A41: アメリカ合衆国 | B41: 0.0012
A42: 韓国 | B42: 0.0006
A44: 興味・関心
A45: コミュニティ | B45: 人数
A46: 沖縄 | B46: 215
...
